<?xml version='1.0'?>
<sdf version='1.9'> 
  <model name='bicopter_with_standoffs'>
  <static>false</static>
  <pose>0 0 0.2 0 0 0</pose> <!--원래 값 0 0 0.194923 0 0 0 -->
    <link name='base_link'>
      <velocity_decay>
        <linear>0.0</linear>
        <angular>0.0</angular>
      </velocity_decay>
      <inertial>
        <pose>0.002973 0.001387 0.095001 0 -0 0</pose> <!--원래 값 0.002973 0.001387 0.095001 0 -0 0-->
        <mass>3</mass> <!--원래 값 mass 0.390996-->
        <inertia>
          <ixx>0.00019185</ixx>
          <ixy>4.02647e-07</ixy>
          <ixz>-7.71289e-06</ixz> <!--원래 값 -7.71289e-06 -->
          <iyy>0.000465506</iyy>
          <iyz>-7.27837e-14</iyz> <!--원래 값 -7.27837e-14 -->
          <izz>0.000526809</izz>
        </inertia>
      </inertial>
      <collision name='base_link_collision'>
        <pose>0 0 0 0 -0 0</pose> <!-- 원래 값 : 0 0 0 0 -0 0 -->
        <geometry>
          <mesh>
            <scale>1 1 1</scale>
            <uri>model://bicopter_with_standoffs/meshes/base_link.STL</uri>
          </mesh>
        </geometry>
        <material>
          <!--script>
            <name>Gazebo/DarkGrey</name>
          </script-->
          <ambient>.175 .175 .175  1.0</ambient>
          <diffuse>.175 .175 .175  1.0</diffuse>
          <specular>.175 .175 .175 1.000000</specular>
        </material>
      </collision>
      <visual name='base_link_visual'>
        <pose>0 0 0 0 -0 0</pose>
        <geometry>
          <mesh>
            <scale>1 1 1</scale>
            <uri>model://bicopter_with_standoffs/meshes/base_link.STL</uri>
          </mesh>_motor_model.so
        </geometry>
      </visual> pose
    </link>
    <joint name='ser0' type='revolute'>
      <pose relative_to='base_link'>0.010312 0.15468 0.15176 0.018488 0 3.14159</pose>
      <parent>base_link</parent>
      <child>ccw-servo</child>
      <axis>
        <xyz>0 -1 0</xyz>
        <limit>    
          <lower>-0.5</lower>
          <upper>0.5</upper>
          <effort>0</effort>
          <velocity>0</velocity>
        </limit>
        <dynamics>
          <spring_reference>0</spring_reference>
          <spring_stiffness>0</spring_stiffness>
        </dynamics>
      </axis>
    </joint>
    <link name="ccw-servo">
      <pose relative_to='ser0'>0 0 0 0 -0 0</pose>
      <inertial>
        <pose>-5e-06 -0.003367 0.021721 0 -0 0</pose>
        <mass>0.0318045</mass>
        <inertia>
          <ixx>4.59202e-06</ixx>
          <ixy>-7.94305e-11</ixy>
          <ixz>-1.03122e-09</ixz>    
          <iyy>3.56948e-06</iyy>
          <iyz>1.17656e-07</iyz>
          <izz>5.80439e-06</izz>
        </inertia>
      </inertial>
      <collision name='ccw-servo_collision'>
        <pose>0 0 0 0 -0 0</pose>
        <geometry>
          <mesh>
            <scale>1 1 1</scale>
            <uri>model://bicopter_with_standoffs/meshes/ccw-servo.STL</uri>
          </mesh> pose
        </geometry>
      </collision>
      <visual name='ccw-servo_visual'>
        <pose>0 0 0 0 -0 0</pose>
        <geometry>
          <mesh>
            <scale>1 1 1</scale>
            <uri>model://bicopter_with_standoffs/meshes/ccw-servo.STL</uri>
          </mesh>
        </geometry>
      </visual>
    </link>
    <joint name='mot0' type='revolute'>
      <pose relative_to='ccw-servo'>0 -0.004 0.0425 0 -0 0</pose>
      <parent>ccw-servo</parent>
      <child>ccw-mot</child>
      <axis>
        <xyz>0 0 -1</xyz>
        <limit>_motor_model.so
          <effort>100</effort>
          <velocity>100</velocity>
          <lower>-1e+16</lower>
          <upper>1e+16</upper>
        </limit>
        <dynamics>
          <spring_reference>0</spring_reference>
          <spring_stiffness>0</spring_stiffness>
        </dynamics>
      </axis>
    </joint>
    <link name="ccw-mot">
      <pose relative_to='mot0'>0 0 0 0 -0 0</pose>
      <inertial>
        <pose>7e-06 -1.2e-05 0.017767 0 -0 0</pose>
        <mass>0.0136328</mass>
        <inertia>
          <ixx>4.42921e-06</ixx>
          <ixy>9.45518e-10</ixy>
          <ixz>4.79661e-09</ixz>
          <iyy>4.42799e-06</iyy>
          <iyz>-2.84067e-08</iyz>
          <izz>8.68181e-06</izz>_motor_model.so
        </inertia>
      </inertial>
      <collision name='ccw-mot_collision'>
        <pose>0 0 0 0 -0 0</pose>
        <geometry>
          <mesh>    
            <scale>1 1 1</scale>
            <uri>model://bicopter_with_standoffs/meshes/ccw-mot.STL</uri>
          </mesh>
        </geometry>
        <material>
          <!--script>
            <name>Gazebo/Blue</name>
            <uri>__default__</uri>
          </script-->
          <ambient>0 0 1</ambient>
          <diffuse>0 0 1</diffuse>
          <specular>0.1 0.1 0.1 1</specular>
        </material>
      </collision>
      <visual name='ccw-mot_visual'>
        <pose>0 0 0 0 -0 0</pose>
        <geometry>
          <mesh>
            <scale>1 1 1</scale>
            <uri>model://bicopter_with_standoffs/meshes/ccw-mot.STL</uri>
          </mesh>
        </geometry>
      </visual>
    </link>
    <joint name='ser1' type='revolute'>
      <pose relative_to='base_link'>0.010312 -0.14923 0.15181 -0.018488 0 -3.14159</pose>
      <parent>base_link</parent>
      <child>cw-servo</child>
      <axis>    
        <xyz>0 1 0</xyz>
        <limit>
          <lower>-0.5</lower>
          <upper>0.5</upper>
          <effort>0</effort>
          <velocity>0</velocity>
        </limit>
        <dynamics>
          <spring_reference>0</spring_reference>
          <spring_stiffness>0</spring_stiffness>
        </dynamics>
      </axis>
    </joint>
    <link name="cw-servo">
      <pose relative_to='ser1'>0 0 0 0 -0 0</pose>
      <inertial>
        <pose>4e-06 0.00321 0.020676 0 -0 0</pose>
        <mass>0.0318045</mass>
        <inertia>    
          <ixx>4.59504e-06</ixx>
          <ixy>1.40278e-09</ixy>
          <ixz>7.07896e-10</ixz>
          <iyy>3.56647e-06</iyy>
          <iyz>-1.14994e-07</iyz>_motor_model.so
          <izz>5.80439e-06</izz>
        </inertia>
      </inertial>
      <collision name='cw-servo_collision'>
        <pose>0 0 0 0 -0 0</pose>
        <geometry>
          <mesh>
            <scale>1 1 1</scale>
            <uri>model://bicopter_with_standoffs/meshes/cw-servo.STL</uri>
          </mesh>
        </geometry>
      </collision>
      <visual name='cw-servo_visual'>
        <pose>0 0 0 0 -0 0</pose>
        <geometry>
          <mesh>
            <scale>1 1 1</scale>
            <uri>model://bicopter_with_standoffs/meshes/cw-servo.STL</uri>
          </mesh>
        </geometry>
      </visual>
    </link>
    <joint name='mot1' type='revolute'>
      <pose relative_to='cw-servo'>0 0.003829 0.041455 0 -0 0</pose>
      <parent>cw-servo</parent>
      <child>cw-mot</child>
      <axis>
        <xyz>0 0 -1</xyz> <!-- 원래 값 : -1 -->
        <limit>
          <effort>100</effort> <!-- 원래 값 : 100 -->
          <velocity>100</velocity>    <!-- 원래 값 : 100 -->
          <lower>-1e+16</lower>
          <upper>1e+16</upper>
        </limit>
        <dynamics>
          <spring_reference>0</spring_reference>
          <spring_stiffness>0</spring_stiffness>
        </dynamics>
      </axis>
    </joint>
    <link name="cw-mot">
      <pose relative_to='mot1'>0 0 0 0 -0 0</pose>
      <inertial>
        <pose>-0 9e-06 0.017847 0 -0 0</pose>
        <mass>0.0136338</mass>
        <inertia>
          <ixx>4.42778e-06</ixx>
          <ixy>6.06547e-11</ixy>
          <ixz>1.00593e-08</ix</sdf>z>
          <iyy>4.42787e-06</iyy>
          <iyz>2.69765e-08</iyz>
          <izz>8.67976e-06</izz>
        </inertia>
      </inertial>
      <collision name='cw-mot_collision'>
        <pose>0 0 0 0 -0 0</pose>
        <geometry>
          <mesh>
            <scale>1 1 1</scale>
            <uri>model://bicopter_with_standoffs/meshes/cw-mot.STL</uri>
          </mesh>
        </geometry>
      </collision>
      <visual name='cw-mot_visual'>
        <pose>0 0 0 0 -0 0</pose>
        <geometry>
          <mesh>
            <scale>1 1 1</scale>
            <uri>model://bicopter_with_standoffs/meshes/cw-mot.STL</uri>
          </mesh>
        </geometry>
        <material>
          <script>
            <name>Gazebo/DarkGrey</name>
            <uri>file://media/materials/scripts/gazebo.material</uri>
          </script>
        </material>
      </visual>
      </link>
      
      <gravity>1</gravity>
      <velocity_decay/>
      
      <link name='imu_link'>
      <inertial>
        <pose>0.002973 0.001387 0.095001 0 -0 0</pose>
        <mass>0.390996</mass>
        <inertia>
          <ixx>0.00019185</ixx>
          <ixy>4.02647e-07</ixy>
          <ixz>-7.71289e-06</ixz>
          <iyy>0.000465506</iyy>
          <iyz>-7.27837e-14</iyz>
          <izz>0.000526809</izz>
        </inertia>
      </inertial>
      <sensor name="imu_sensor" type="imu">
        <pose>0 0 0 3.141593 0 0</pose>bicopter_with_standoffs
        <always_on>1</always_on>
        <update_rate>1000.0</update_rate>
      </sensor>
    </link>
    <joint name='imu_joint' type='revolute'>
      <child>imu_link</child>
      <parent>base_link</parent>
      <axis>
        <xyz>0 0 1</xyz>
        <limit>
          <lower>0</lower>
          <upper>0</upper>
          <effort>0</effort>
          <velocity>0</velocity>
        </limit>
        <dynamics>
          <damping>1.0</damping>
        </dynamics>
      </axis>
    </joint>
    
</model>
</sdf>
